setTimeout(() => {
  console.log("Hacking wifi.... Please wait...");
}, 1000);

try {
  console.log(rahul);
} catch (error) {
  // console.log(error); // consoles its own error which should occur. Not throwing error but consoling that error
  console.log("balle balle error from catch");
}

setTimeout(() => {
  console.log("Fetching username and password.... Please wait...");
}, 2000);

setTimeout(() => {
  console.log("Hacking Rahul's facebook id.... Please wait...");
}, 3000);

setTimeout(() => {
  console.log(
    "Username and password of Rahul (+919356700001) fetched.... Please wait..."
  );
}, 4000);
